import pytest
import json
import asyncio
from conftest import (
    auth_headers,
    client,
    test_create_project_init,
    select,
    db_models,
    async_client,
)
from sqlalchemy.exc import SQLAlchemyError
from fastapi import WebSocketException, WebSocket
from api.v1.routers import ws
from models import exceptions, schemas
from unittest.mock import AsyncMock
from starlette.requests import Request


@pytest.mark.asyncio
async def test_send_message_to_project(
    async_client, auth_headers, test_create_project_init
):
    response = await async_client.post(
        "/chat/1", headers=auth_headers, json={"content": "Enviando mensaje por http"}
    )
    assert response.status_code == 200
    assert response.json() == {
        "detail": "Mensaje enviado con exito al proyecto 1 por user 1"
    }


def test_get_chat(client, auth_headers):
    response = client.get("/chat/1", headers=auth_headers)
    assert response.status_code == 200
    messages = response.json()
    assert isinstance(messages, list)
    for message in messages:
        assert all(
            key in message
            for key in ["chat_id", "project_id", "user_id", "message", "timestamp"]
        )


def test_get_chat_error(mocker):
    session_mock = mocker.Mock()
    mock_user = mocker.Mock(spec=db_models.User)
    mock_request = mocker.Mock(spec=Request)

    # Excepcion chat no encontrado
    session_mock.exec.return_value.all.return_value = []

    with pytest.raises(exceptions.ChatNotFoundError):
        ws.get_chat(
            request=mock_request, project_id=1, user=mock_user, session=session_mock
        )

    # Prueba la excepcion de DB
    session_mock.exec.side_effect = SQLAlchemyError("Error en base de datos")

    with pytest.raises(exceptions.DatabaseError):
        ws.get_chat(
            request=mock_request, project_id=1, user=mock_user, session=session_mock
        )


@pytest.mark.asyncio
async def test_send_message_to_project_error(mocker, auth_headers):
    message_mocker = mocker.Mock(spec=schemas.GroupMessagePayload)
    message_mocker.content = "Probando error en base de datos"

    user_mock = mocker.Mock(spec=db_models.User)
    session_mock = mocker.Mock()

    mocker.patch("api.v1.routers.ws.found_user_in_project_or_404", return_value=1)

    session_mock.add.side_effect = SQLAlchemyError("Error en base de datos")

    with pytest.raises(exceptions.DatabaseError):
        await ws.send_message_to_project(
            project_id=1,
            message_payload=message_mocker,
            user=user_mock,
            session=session_mock,
        )

    session_mock.rollback.assert_called_once()


def test_verify_user_in_project_error(mocker):
    session_mock = mocker.Mock()

    # Excepcion usuario no autorizado
    session_mock.exec.return_value.first.return_value = []

    with pytest.raises(exceptions.NotAuthorized):
        ws.verify_user_in_project(user_id=1, project_id=1, session=session_mock)

    # Excepcion project no encontrado
    session_mock.get.return_value = []

    with pytest.raises(exceptions.ProjectNotFoundError):
        ws.verify_user_in_project(user_id=1, project_id=1, session=session_mock)


@pytest.mark.asyncio
async def test_get_current_user_ws_header_error(mocker):
    session_mock = mocker.Mock()

    ws_mock = mocker.Mock(spec=WebSocket)
    ws_mock.headers = {}
    ws_mock.close = AsyncMock()

    with pytest.raises(WebSocketException):
        await ws.get_current_user_ws(session=session_mock, websocket=ws_mock)

    ws_mock.close.assert_awaited_once_with(code=1008, reason="Authentication Error")


@pytest.mark.asyncio
async def test_get_current_user_ws_format_error(mocker):
    session_mock = mocker.Mock()

    ws_mock = mocker.Mock(spec=WebSocket)
    ws_mock.headers = {"Authorization": "hola"}
    ws_mock.close = AsyncMock()

    with pytest.raises(WebSocketException):
        await ws.get_current_user_ws(session=session_mock, websocket=ws_mock)

    ws_mock.close.assert_awaited_once_with(code=1008, reason="Invalid token format")


@pytest.mark.asyncio
async def test_get_current_user_ws_user_not_found_error(mocker):
    session_mock = mocker.Mock()

    ws_mock = mocker.Mock(spec=WebSocket)
    ws_mock.headers = {"Authorization": "Bearer "}
    ws_mock.close = AsyncMock()

    with pytest.raises(WebSocketException):
        await ws.get_current_user_ws(session=session_mock, websocket=ws_mock)

    ws_mock.close.assert_awaited_once_with(code=1008, reason="User not found for token")


@pytest.mark.asyncio
async def test_websocket_endpoint_not_found_project_error(mocker):
    # Session
    session_mock = mocker.Mock()

    # WebSocket simulado
    ws_mock = mocker.Mock(spec=WebSocket)
    ws_mock.headers = {"Authorization": "Bearer token"}
    ws_mock.close = AsyncMock()

    # Usuario simulado
    mock_user = mocker.Mock()
    mock_user.user_id = 1
    mocker.patch("api.v1.routers.ws.get_current_user_ws", return_value=mock_user)

    # Forzar que verify_user_in_project lance la excepci贸n
    mocker.patch(
        "api.v1.routers.ws.verify_user_in_project",
        side_effect=exceptions.ProjectNotFoundError(project_id=999),
    )

    # Ejecutar el endpoint
    await ws.websocket_endpoint(websocket=ws_mock, project_id=999, session=session_mock)

    # Verificar que se cerr贸 con el mensaje correcto
    ws_mock.close.assert_awaited_once_with(code=1008, reason="Proyect 999 not found")


@pytest.mark.asyncio
async def test_websocket_endpoint_not_authorized_error(mocker):
    # Session
    session_mock = mocker.Mock()

    # WebSocket simulado
    ws_mock = mocker.Mock(spec=WebSocket)
    ws_mock.headers = {"Authorization": "Bearer token"}
    ws_mock.close = AsyncMock()

    # Usuario simulado
    mock_user = mocker.Mock()
    mock_user.user_id = 1
    mocker.patch("api.v1.routers.ws.get_current_user_ws", return_value=mock_user)

    # Forzar que verify_user_in_project lance la excepci贸n
    mocker.patch(
        "api.v1.routers.ws.verify_user_in_project",
        side_effect=exceptions.NotAuthorized(user_id=1),
    )

    # Ejecutar el endpoint
    await ws.websocket_endpoint(websocket=ws_mock, project_id=999, session=session_mock)

    # Verificar que se cerr贸 con el mensaje correcto
    ws_mock.close.assert_awaited_once_with(
        code=1008, reason="User not authorized for proyect 999"
    )

